<?xml version="1.0"?>
<sdf version="1.5">
  <model name="temp_bot">
    <static>false</static>
    <pose>0 0 0.3 0 -0 0</pose>
    <link name="link_Core_0">
      <self_collide>0</self_collide>
      <pose>6.92599e-310 2.122e-314 1.12466e-312 0 -0 0</pose>
      <inertial>
        <mass>55.4</mass>
        <inertia>
          <ixx>1.99648</ixx>
          <ixy>0</ixy>
          <ixz>0</ixz>
          <iyy>1.99648</iyy>
          <iyz>0</iyz>
          <izz>1.99648</izz>
        </inertia>
      </inertial>
      <collision name="collision">
        <pose>6.92599e-310 4.65218e-317 6.92599e-310 0 -0 0</pose>
        <geometry>
          <box>
            <size>0.465 0.465 0.465</size>
          </box>
        </geometry>
        <surface>
          <friction>
            <ode>
              <mu>1</mu>
              <mu2>1</mu2>
              <fdir1>9.43281e-144 1.6336e-18 1.95215e+233</fdir1>
              <slip1>0.1</slip1>
              <slip2>0.1</slip2>
            </ode>
            <bullet>
              <friction>1</friction>
              <friction2>1</friction2>
              <fdir1>9.43281e-144 1.6336e-18 1.95215e+233</fdir1>
              <rolling_friction>1</rolling_friction>
            </bullet>
          </friction>
        </surface>
      </collision>
      <visual name="visual">
        <pose>6.92599e-310 0 0 0 -0 0</pose>
        <geometry>
          <box>
            <size>0.465 0.465 0.465</size>
          </box>
        </geometry>
      </visual>
    </link>
    <link name="link_Hip1_0">
      <self_collide>0</self_collide>
      <pose>-0.24 4.65269e-317 4.65351e-317 -1.5708 0 3.14159</pose>
      <inertial>
        <mass>7</mass>
        <inertia>
          <ixx>0.134867</ixx>
          <ixy>0</ixy>
          <ixz>0</ixz>
          <iyy>0.0675646</iyy>
          <iyz>0</iyz>
          <izz>0.0675646</izz>
        </inertia>
      </inertial>
      <collision name="collision">
        <pose>6.92599e-310 0 0 0 -0 0</pose>
        <geometry>
          <box>
            <size>0.015 0.34 0.34</size>
          </box>
        </geometry>
        <surface>
          <friction>
            <ode>
              <mu>1</mu>
              <mu2>1</mu2>
              <fdir1>2.87124e-27 4.47273e+251 6.99641e+228</fdir1>
              <slip1>0.1</slip1>
              <slip2>0.1</slip2>
            </ode>
            <bullet>
              <friction>1</friction>
              <friction2>1</friction2>
              <fdir1>2.87124e-27 4.47273e+251 6.99641e+228</fdir1>
              <rolling_friction>1</rolling_friction>
            </bullet>
          </friction>
        </surface>
      </collision>
      <visual name="visual">
        <pose>6.92599e-310 0 0 0 -0 0</pose>
        <geometry>
          <box>
            <size>0.015 0.34 0.34</size>
          </box>
        </geometry>
      </visual>
    </link>
    <link name="link_Hip1_2">
      <self_collide>0</self_collide>
      <pose>-0.3235 9.30576e-317 4.65351e-317 -1.5708 0 3.14159</pose>
      <inertial>
        <mass>1.2</mass>
        <inertia>
          <ixx>0.01256</ixx>
          <ixy>0</ixy>
          <ixz>0</ixz>
          <iyy>0.00424</iyy>
          <iyz>0</iyz>
          <izz>0.0148</izz>
        </inertia>
      </inertial>
      <collision name="collision">
        <pose>6.92599e-310 0 0 0 -0 0</pose>
        <geometry>
          <box>
            <size>0.18 0.34 0.1</size>
          </box>
        </geometry>
        <surface>
          <friction>
            <ode>
              <mu>1</mu>
              <mu2>1</mu2>
              <fdir1>1.64968e-18 3.21781e+257 7.66955e+228</fdir1>
              <slip1>0.1</slip1>
              <slip2>0.1</slip2>
            </ode>
            <bullet>
              <friction>1</friction>
              <friction2>1</friction2>
              <fdir1>1.64968e-18 3.21781e+257 7.66955e+228</fdir1>
              <rolling_friction>1</rolling_friction>
            </bullet>
          </friction>
        </surface>
      </collision>
      <visual name="visual">
        <pose>6.92599e-310 0 0 0 -0 0</pose>
        <geometry>
          <box>
            <size>0.18 0.34 0.1</size>
          </box>
        </geometry>
      </visual>
    </link>
    <link name="link_Hip1_3">
      <self_collide>0</self_collide>
      <pose>-0.456 9.30576e-317 4.65351e-317 -1.5708 0 3.14159</pose>
      <inertial>
        <mass>9</mass>
        <inertia>
          <ixx>0.0942</ixx>
          <ixy>0</ixy>
          <ixz>0</ixz>
          <iyy>0.0525188</iyy>
          <iyz>0</iyz>
          <izz>0.131719</izz>
        </inertia>
      </inertial>
      <collision name="collision">
        <pose>6.92599e-310 0 0 0 -0 0</pose>
        <geometry>
          <box>
            <size>0.245 0.34 0.1</size>
          </box>
        </geometry>
        <surface>
          <friction>
            <ode>
              <mu>1</mu>
              <mu2>1</mu2>
              <fdir1>2.87124e-27 2.47403e-259 3.21781e+257</fdir1>
              <slip1>0.1</slip1>
              <slip2>0.1</slip2>
            </ode>
            <bullet>
              <friction>1</friction>
              <friction2>1</friction2>
              <fdir1>2.87124e-27 2.47403e-259 3.21781e+257</fdir1>
              <rolling_friction>1</rolling_friction>
            </bullet>
          </friction>
        </surface>
      </collision>
      <visual name="visual">
        <pose>6.92599e-310 0 0 0 -0 0</pose>
        <geometry>
          <box>
            <size>0.245 0.34 0.1</size>
          </box>
        </geometry>
        <material>
          <script>
            <uri>file://media/materials/scripts/gazebo.material</uri>
            <name>Gazebo/Black</name>
          </script>
        </material>
      </visual>
    </link>
    <link name="link_Hip1_1">
      <self_collide>0</self_collide>
      <pose>-0.587 9.30576e-317 4.65351e-317 -1.5708 0 3.14159</pose>
      <inertial>
        <mass>7</mass>
        <inertia>
          <ixx>0.134867</ixx>
          <ixy>0</ixy>
          <ixz>0</ixz>
          <iyy>0.0675646</iyy>
          <iyz>0</iyz>
          <izz>0.0675646</izz>
        </inertia>
      </inertial>
      <collision name="collision">
        <pose>6.92599e-310 0 0 0 -0 0</pose>
        <geometry>
          <box>
            <size>0.015 0.34 0.34</size>
          </box>
        </geometry>
        <surface>
          <friction>
            <ode>
              <mu>1</mu>
              <mu2>1</mu2>
              <fdir1>6.99641e+228 2.87124e-27 2.45653e+198</fdir1>
              <slip1>0.1</slip1>
              <slip2>0.1</slip2>
            </ode>
            <bullet>
              <friction>1</friction>
              <friction2>1</friction2>
              <fdir1>6.99641e+228 2.87124e-27 2.45653e+198</fdir1>
              <rolling_friction>1</rolling_friction>
            </bullet>
          </friction>
        </surface>
      </collision>
      <visual name="visual">
        <pose>6.92599e-310 0 0 0 -0 0</pose>
        <geometry>
          <box>
            <size>0.015 0.34 0.34</size>
          </box>
        </geometry>
      </visual>
    </link>
    <link name="link_UpperLeg1_0">
      <self_collide>0</self_collide>
      <pose>-0.827 9.30576e-317 4.65351e-317 -4.44089e-16 0 3.14159</pose>
      <inertial>
        <mass>14.9</mass>
        <inertia>
          <ixx>0.536959</ixx>
          <ixy>0</ixy>
          <ixz>0</ixz>
          <iyy>0.536959</iyy>
          <iyz>0</iyz>
          <izz>0.536959</izz>
        </inertia>
      </inertial>
      <collision name="collision">
        <pose>6.92599e-310 0 0 0 -0 0</pose>
        <geometry>
          <box>
            <size>0.465 0.465 0.465</size>
          </box>
        </geometry>
        <surface>
          <friction>
            <ode>
              <mu>1</mu>
              <mu2>1</mu2>
              <fdir1>4.63799e-317 4.63803e-317 4.63824e-317</fdir1>
              <slip1>0.1</slip1>
              <slip2>0.1</slip2>
            </ode>
            <bullet>
              <friction>1</friction>
              <friction2>1</friction2>
              <fdir1>4.63799e-317 4.63803e-317 4.63824e-317</fdir1>
              <rolling_friction>1</rolling_friction>
            </bullet>
          </friction>
        </surface>
      </collision>
      <visual name="visual">
        <pose>6.92599e-310 0 0 0 -0 0</pose>
        <geometry>
          <box>
            <size>0.465 0.465 0.465</size>
          </box>
        </geometry>
      </visual>
    </link>
    <link name="link_Knee1_0">
      <self_collide>0</self_collide>
      <pose>-1.067 9.30576e-317 4.65351e-317 -4.44089e-16 -0 3.14159</pose>
      <inertial>
        <mass>7</mass>
        <inertia>
          <ixx>0.134867</ixx>
          <ixy>0</ixy>
          <ixz>0</ixz>
          <iyy>0.0675646</iyy>
          <iyz>0</iyz>
          <izz>0.0675646</izz>
        </inertia>
      </inertial>
      <collision name="collision">
        <pose>0 0 0 0 -0 0</pose>
        <geometry>
          <box>
            <size>0.015 0.34 0.34</size>
          </box>
        </geometry>
        <surface>
          <friction>
            <ode>
              <mu>1</mu>
              <mu2>1</mu2>
              <fdir1>1.15102e-319 0 0</fdir1>
              <slip1>0.1</slip1>
              <slip2>0.1</slip2>
            </ode>
            <bullet>
              <friction>1</friction>
              <friction2>1</friction2>
              <fdir1>1.15102e-319 0 0</fdir1>
              <rolling_friction>1</rolling_friction>
            </bullet>
          </friction>
        </surface>
      </collision>
      <visual name="visual">
        <pose>0 0 0 0 -0 0</pose>
        <geometry>
          <box>
            <size>0.015 0.34 0.34</size>
          </box>
        </geometry>
      </visual>
    </link>
    <link name="link_Knee1_2">
      <self_collide>0</self_collide>
      <pose>-1.1505 9.30576e-317 4.65351e-317 -4.44089e-16 -0 3.14159</pose>
      <inertial>
        <mass>1.2</mass>
        <inertia>
          <ixx>0.01256</ixx>
          <ixy>0</ixy>
          <ixz>0</ixz>
          <iyy>0.00424</iyy>
          <iyz>0</iyz>
          <izz>0.0148</izz>
        </inertia>
      </inertial>
      <collision name="collision">
        <pose>0 0 0 0 -0 0</pose>
        <geometry>
          <box>
            <size>0.18 0.34 0.1</size>
          </box>
        </geometry>
        <surface>
          <friction>
            <ode>
              <mu>1</mu>
              <mu2>1</mu2>
              <fdir1>3.10334e+39 5.14097e+151 9.92239e+260</fdir1>
              <slip1>0.1</slip1>
              <slip2>0.1</slip2>
            </ode>
            <bullet>
              <friction>1</friction>
              <friction2>1</friction2>
              <fdir1>3.10334e+39 5.14097e+151 9.92239e+260</fdir1>
              <rolling_friction>1</rolling_friction>
            </bullet>
          </friction>
        </surface>
      </collision>
      <visual name="visual">
        <pose>0 0 0 0 -0 0</pose>
        <geometry>
          <box>
            <size>0.18 0.34 0.1</size>
          </box>
        </geometry>
      </visual>
    </link>
    <link name="link_Knee1_3">
      <self_collide>0</self_collide>
      <pose>-1.283 9.30576e-317 4.65351e-317 -4.44089e-16 -0 3.14159</pose>
      <inertial>
        <mass>9</mass>
        <inertia>
          <ixx>0.0942</ixx>
          <ixy>0</ixy>
          <ixz>0</ixz>
          <iyy>0.0525188</iyy>
          <iyz>0</iyz>
          <izz>0.131719</izz>
        </inertia>
      </inertial>
      <collision name="collision">
        <pose>0 0 0 0 -0 0</pose>
        <geometry>
          <box>
            <size>0.245 0.34 0.1</size>
          </box>
        </geometry>
        <surface>
          <friction>
            <ode>
              <mu>1</mu>
              <mu2>1</mu2>
              <fdir1>0 0 0</fdir1>
              <slip1>0.1</slip1>
              <slip2>0.1</slip2>
            </ode>
            <bullet>
              <friction>1</friction>
              <friction2>1</friction2>
              <fdir1>0 0 0</fdir1>
              <rolling_friction>1</rolling_friction>
            </bullet>
          </friction>
        </surface>
      </collision>
      <visual name="visual">
        <pose>0 0 0 0 -0 0</pose>
        <geometry>
          <box>
            <size>0.245 0.34 0.1</size>
          </box>
        </geometry>
        <material>
          <script>
            <uri>file://media/materials/scripts/gazebo.material</uri>
            <name>Gazebo/Black</name>
          </script>
        </material>
      </visual>
    </link>
    <link name="link_Knee1_1">
      <self_collide>0</self_collide>
      <pose>-1.414 9.30576e-317 4.65351e-317 -4.44089e-16 -0 3.14159</pose>
      <inertial>
        <mass>7</mass>
        <inertia>
          <ixx>0.134867</ixx>
          <ixy>0</ixy>
          <ixz>0</ixz>
          <iyy>0.0675646</iyy>
          <iyz>0</iyz>
          <izz>0.0675646</izz>
        </inertia>
      </inertial>
      <collision name="collision">
        <pose>0 0 0 0 -0 0</pose>
        <geometry>
          <box>
            <size>0.015 0.34 0.34</size>
          </box>
        </geometry>
        <surface>
          <friction>
            <ode>
              <mu>1</mu>
              <mu2>1</mu2>
              <fdir1>0 0 0</fdir1>
              <slip1>0.1</slip1>
              <slip2>0.1</slip2>
            </ode>
            <bullet>
              <friction>1</friction>
              <friction2>1</friction2>
              <fdir1>0 0 0</fdir1>
              <rolling_friction>1</rolling_friction>
            </bullet>
          </friction>
        </surface>
      </collision>
      <visual name="visual">
        <pose>0 0 0 0 -0 0</pose>
        <geometry>
          <box>
            <size>0.015 0.34 0.34</size>
          </box>
        </geometry>
      </visual>
    </link>
    <link name="link_LowerLeg1_0">
      <self_collide>0</self_collide>
      <pose>-1.654 9.30576e-317 4.65351e-317 -4.44089e-16 -0 3.14159</pose>
      <inertial>
        <mass>14.9</mass>
        <inertia>
          <ixx>0.536959</ixx>
          <ixy>0</ixy>
          <ixz>0</ixz>
          <iyy>0.536959</iyy>
          <iyz>0</iyz>
          <izz>0.536959</izz>
        </inertia>
      </inertial>
      <collision name="collision">
        <pose>0 0 0 0 -0 0</pose>
        <geometry>
          <box>
            <size>0.465 0.465 0.465</size>
          </box>
        </geometry>
        <surface>
          <friction>
            <ode>
              <mu>1</mu>
              <mu2>1</mu2>
              <fdir1>4.67241e-317 4.67245e-317 4.67266e-317</fdir1>
              <slip1>0.1</slip1>
              <slip2>0.1</slip2>
            </ode>
            <bullet>
              <friction>1</friction>
              <friction2>1</friction2>
              <fdir1>4.67241e-317 4.67245e-317 4.67266e-317</fdir1>
              <rolling_friction>1</rolling_friction>
            </bullet>
          </friction>
        </surface>
      </collision>
      <visual name="visual">
        <pose>0 0 0 0 -0 0</pose>
        <geometry>
          <box>
            <size>0.465 0.465 0.465</size>
          </box>
        </geometry>
      </visual>
    </link>
    <link name="link_Hip2_0">
      <self_collide>0</self_collide>
      <pose>0.24 0 0 -1.5708 0 0</pose>
      <inertial>
        <mass>7</mass>
        <inertia>
          <ixx>0.134867</ixx>
          <ixy>0</ixy>
          <ixz>0</ixz>
          <iyy>0.0675646</iyy>
          <iyz>0</iyz>
          <izz>0.0675646</izz>
        </inertia>
      </inertial>
      <collision name="collision">
        <pose>0 0 0 0 -0 0</pose>
        <geometry>
          <box>
            <size>0.015 0.34 0.34</size>
          </box>
        </geometry>
        <surface>
          <friction>
            <ode>
              <mu>1</mu>
              <mu2>1</mu2>
              <fdir1>0 0 0</fdir1>
              <slip1>0.1</slip1>
              <slip2>0.1</slip2>
            </ode>
            <bullet>
              <friction>1</friction>
              <friction2>1</friction2>
              <fdir1>0 0 0</fdir1>
              <rolling_friction>1</rolling_friction>
            </bullet>
          </friction>
        </surface>
      </collision>
      <visual name="visual">
        <pose>0 0 0 0 -0 0</pose>
        <geometry>
          <box>
            <size>0.015 0.34 0.34</size>
          </box>
        </geometry>
      </visual>
    </link>
    <link name="link_Hip2_2">
      <self_collide>0</self_collide>
      <pose>0.3235 0 0 -1.5708 0 0</pose>
      <inertial>
        <mass>1.2</mass>
        <inertia>
          <ixx>0.01256</ixx>
          <ixy>0</ixy>
          <ixz>0</ixz>
          <iyy>0.00424</iyy>
          <iyz>0</iyz>
          <izz>0.0148</izz>
        </inertia>
      </inertial>
      <collision name="collision">
        <pose>0 0 0 0 -0 0</pose>
        <geometry>
          <box>
            <size>0.18 0.34 0.1</size>
          </box>
        </geometry>
        <surface>
          <friction>
            <ode>
              <mu>1</mu>
              <mu2>1</mu2>
              <fdir1>0 0 0</fdir1>
              <slip1>0.1</slip1>
              <slip2>0.1</slip2>
            </ode>
            <bullet>
              <friction>1</friction>
              <friction2>1</friction2>
              <fdir1>0 0 0</fdir1>
              <rolling_friction>1</rolling_friction>
            </bullet>
          </friction>
        </surface>
      </collision>
      <visual name="visual">
        <pose>0 0 0 0 -0 0</pose>
        <geometry>
          <box>
            <size>0.18 0.34 0.1</size>
          </box>
        </geometry>
      </visual>
    </link>
    <link name="link_Hip2_3">
      <self_collide>0</self_collide>
      <pose>0.456 0 0 -1.5708 0 0</pose>
      <inertial>
        <mass>9</mass>
        <inertia>
          <ixx>0.0942</ixx>
          <ixy>0</ixy>
          <ixz>0</ixz>
          <iyy>0.0525188</iyy>
          <iyz>0</iyz>
          <izz>0.131719</izz>
        </inertia>
      </inertial>
      <collision name="collision">
        <pose>0 0 0 0 -0 0</pose>
        <geometry>
          <box>
            <size>0.245 0.34 0.1</size>
          </box>
        </geometry>
        <surface>
          <friction>
            <ode>
              <mu>1</mu>
              <mu2>1</mu2>
              <fdir1>0 0 0</fdir1>
              <slip1>0.1</slip1>
              <slip2>0.1</slip2>
            </ode>
            <bullet>
              <friction>1</friction>
              <friction2>1</friction2>
              <fdir1>0 0 0</fdir1>
              <rolling_friction>1</rolling_friction>
            </bullet>
          </friction>
        </surface>
      </collision>
      <visual name="visual">
        <pose>0 0 0 0 -0 0</pose>
        <geometry>
          <box>
            <size>0.245 0.34 0.1</size>
          </box>
        </geometry>
        <material>
          <script>
            <uri>file://media/materials/scripts/gazebo.material</uri>
            <name>Gazebo/Black</name>
          </script>
        </material>
      </visual>
    </link>
    <link name="link_Hip2_1">
      <self_collide>0</self_collide>
      <pose>0.587 0 0 -1.5708 0 0</pose>
      <inertial>
        <mass>7</mass>
        <inertia>
          <ixx>0.134867</ixx>
          <ixy>0</ixy>
          <ixz>0</ixz>
          <iyy>0.0675646</iyy>
          <iyz>0</iyz>
          <izz>0.0675646</izz>
        </inertia>
      </inertial>
      <collision name="collision">
        <pose>0 0 0 0 -0 0</pose>
        <geometry>
          <box>
            <size>0.015 0.34 0.34</size>
          </box>
        </geometry>
        <surface>
          <friction>
            <ode>
              <mu>1</mu>
              <mu2>1</mu2>
              <fdir1>0 0 0</fdir1>
              <slip1>0.1</slip1>
              <slip2>0.1</slip2>
            </ode>
            <bullet>
              <friction>1</friction>
              <friction2>1</friction2>
              <fdir1>0 0 0</fdir1>
              <rolling_friction>1</rolling_friction>
            </bullet>
          </friction>
        </surface>
      </collision>
      <visual name="visual">
        <pose>0 0 0 0 -0 0</pose>
        <geometry>
          <box>
            <size>0.015 0.34 0.34</size>
          </box>
        </geometry>
      </visual>
    </link>
    <link name="link_UpperLeg2_0">
      <self_collide>0</self_collide>
      <pose>0.827 0 0 -3.14159 0 0</pose>
      <inertial>
        <mass>14.9</mass>
        <inertia>
          <ixx>0.536959</ixx>
          <ixy>0</ixy>
          <ixz>0</ixz>
          <iyy>0.536959</iyy>
          <iyz>0</iyz>
          <izz>0.536959</izz>
        </inertia>
      </inertial>
      <collision name="collision">
        <pose>0 0 0 0 -0 0</pose>
        <geometry>
          <box>
            <size>0.465 0.465 0.465</size>
          </box>
        </geometry>
        <surface>
          <friction>
            <ode>
              <mu>1</mu>
              <mu2>1</mu2>
              <fdir1>4.67787e-317 4.67791e-317 4.67812e-317</fdir1>
              <slip1>0.1</slip1>
              <slip2>0.1</slip2>
            </ode>
            <bullet>
              <friction>1</friction>
              <friction2>1</friction2>
              <fdir1>4.67787e-317 4.67791e-317 4.67812e-317</fdir1>
              <rolling_friction>1</rolling_friction>
            </bullet>
          </friction>
        </surface>
      </collision>
      <visual name="visual">
        <pose>0 0 0 0 -0 0</pose>
        <geometry>
          <box>
            <size>0.465 0.465 0.465</size>
          </box>
        </geometry>
      </visual>
    </link>
    <link name="link_Knee2_0">
      <self_collide>0</self_collide>
      <pose>1.067 0 0 -3.14159 -0 0</pose>
      <inertial>
        <mass>7</mass>
        <inertia>
          <ixx>0.134867</ixx>
          <ixy>0</ixy>
          <ixz>0</ixz>
          <iyy>0.0675646</iyy>
          <iyz>0</iyz>
          <izz>0.0675646</izz>
        </inertia>
      </inertial>
      <collision name="collision">
        <pose>0 0 0 0 -0 0</pose>
        <geometry>
          <box>
            <size>0.015 0.34 0.34</size>
          </box>
        </geometry>
        <surface>
          <friction>
            <ode>
              <mu>1</mu>
              <mu2>1</mu2>
              <fdir1>0 0 0</fdir1>
              <slip1>0.1</slip1>
              <slip2>0.1</slip2>
            </ode>
            <bullet>
              <friction>1</friction>
              <friction2>1</friction2>
              <fdir1>0 0 0</fdir1>
              <rolling_friction>1</rolling_friction>
            </bullet>
          </friction>
        </surface>
      </collision>
      <visual name="visual">
        <pose>0 0 0 0 -0 0</pose>
        <geometry>
          <box>
            <size>0.015 0.34 0.34</size>
          </box>
        </geometry>
      </visual>
    </link>
    <link name="link_Knee2_2">
      <self_collide>0</self_collide>
      <pose>1.1505 0 0 -3.14159 -0 0</pose>
      <inertial>
        <mass>1.2</mass>
        <inertia>
          <ixx>0.01256</ixx>
          <ixy>0</ixy>
          <ixz>0</ixz>
          <iyy>0.00424</iyy>
          <iyz>0</iyz>
          <izz>0.0148</izz>
        </inertia>
      </inertial>
      <collision name="collision">
        <pose>0 0 0 0 -0 0</pose>
        <geometry>
          <box>
            <size>0.18 0.34 0.1</size>
          </box>
        </geometry>
        <surface>
          <friction>
            <ode>
              <mu>1</mu>
              <mu2>1</mu2>
              <fdir1>0 0 0</fdir1>
              <slip1>0.1</slip1>
              <slip2>0.1</slip2>
            </ode>
            <bullet>
              <friction>1</friction>
              <friction2>1</friction2>
              <fdir1>0 0 0</fdir1>
              <rolling_friction>1</rolling_friction>
            </bullet>
          </friction>
        </surface>
      </collision>
      <visual name="visual">
        <pose>0 0 0 0 -0 0</pose>
        <geometry>
          <box>
            <size>0.18 0.34 0.1</size>
          </box>
        </geometry>
      </visual>
    </link>
    <link name="link_Knee2_3">
      <self_collide>0</self_collide>
      <pose>1.283 0 0 -3.14159 -0 0</pose>
      <inertial>
        <mass>9</mass>
        <inertia>
          <ixx>0.0942</ixx>
          <ixy>0</ixy>
          <ixz>0</ixz>
          <iyy>0.0525188</iyy>
          <iyz>0</iyz>
          <izz>0.131719</izz>
        </inertia>
      </inertial>
      <collision name="collision">
        <pose>0 0 0 0 -0 0</pose>
        <geometry>
          <box>
            <size>0.245 0.34 0.1</size>
          </box>
        </geometry>
        <surface>
          <friction>
            <ode>
              <mu>1</mu>
              <mu2>1</mu2>
              <fdir1>0 0 0</fdir1>
              <slip1>0.1</slip1>
              <slip2>0.1</slip2>
            </ode>
            <bullet>
              <friction>1</friction>
              <friction2>1</friction2>
              <fdir1>0 0 0</fdir1>
              <rolling_friction>1</rolling_friction>
            </bullet>
          </friction>
        </surface>
      </collision>
      <visual name="visual">
        <pose>0 0 0 0 -0 0</pose>
        <geometry>
          <box>
            <size>0.245 0.34 0.1</size>
          </box>
        </geometry>
        <material>
          <script>
            <uri>file://media/materials/scripts/gazebo.material</uri>
            <name>Gazebo/Black</name>
          </script>
        </material>
      </visual>
    </link>
    <link name="link_Knee2_1">
      <self_collide>0</self_collide>
      <pose>1.414 0 0 -3.14159 -0 0</pose>
      <inertial>
        <mass>7</mass>
        <inertia>
          <ixx>0.134867</ixx>
          <ixy>0</ixy>
          <ixz>0</ixz>
          <iyy>0.0675646</iyy>
          <iyz>0</iyz>
          <izz>0.0675646</izz>
        </inertia>
      </inertial>
      <collision name="collision">
        <pose>0 0 0 0 -0 0</pose>
        <geometry>
          <box>
            <size>0.015 0.34 0.34</size>
          </box>
        </geometry>
        <surface>
          <friction>
            <ode>
              <mu>1</mu>
              <mu2>1</mu2>
              <fdir1>0 0 0</fdir1>
              <slip1>0.1</slip1>
              <slip2>0.1</slip2>
            </ode>
            <bullet>
              <friction>1</friction>
              <friction2>1</friction2>
              <fdir1>0 0 0</fdir1>
              <rolling_friction>1</rolling_friction>
            </bullet>
          </friction>
        </surface>
      </collision>
      <visual name="visual">
        <pose>0 0 0 0 -0 0</pose>
        <geometry>
          <box>
            <size>0.015 0.34 0.34</size>
          </box>
        </geometry>
      </visual>
    </link>
    <link name="link_LowerLeg2_0">
      <self_collide>0</self_collide>
      <pose>1.654 0 0 -3.14159 -0 0</pose>
      <inertial>
        <mass>14.9</mass>
        <inertia>
          <ixx>0.536959</ixx>
          <ixy>0</ixy>
          <ixz>0</ixz>
          <iyy>0.536959</iyy>
          <iyz>0</iyz>
          <izz>0.536959</izz>
        </inertia>
      </inertial>
      <collision name="collision">
        <pose>0 0 0 0 -0 0</pose>
        <geometry>
          <box>
            <size>0.465 0.465 0.465</size>
          </box>
        </geometry>
        <surface>
          <friction>
            <ode>
              <mu>1</mu>
              <mu2>1</mu2>
              <fdir1>4.68332e-317 4.68335e-317 4.68357e-317</fdir1>
              <slip1>0.1</slip1>
              <slip2>0.1</slip2>
            </ode>
            <bullet>
              <friction>1</friction>
              <friction2>1</friction2>
              <fdir1>4.68332e-317 4.68335e-317 4.68357e-317</fdir1>
              <rolling_friction>1</rolling_friction>
            </bullet>
          </friction>
        </surface>
      </collision>
      <visual name="visual">
        <pose>0 0 0 0 -0 0</pose>
        <geometry>
          <box>
            <size>0.465 0.465 0.465</size>
          </box>
        </geometry>
      </visual>
    </link>
    <joint type="revolute" name="joint_link_Hip1_0_link_Hip1_2">
      <pose>-0.09 0 0 0 -0 0</pose>
      <parent>link_Hip1_0</parent>
      <child>link_Hip1_2</child>
      <axis>
        <xyz>1 0 0 </xyz>
        <use_parent_model_frame>0</use_parent_model_frame>
        <limit>
          <lower>0</lower>
          <upper>0</upper>
          <effort>-1</effort>
          <velocity>-1</velocity>
          <dissipation>1</dissipation>
        </limit>
      </axis>
    </joint>
    <joint type="revolute" name="joint_link_Hip1_3_link_Hip1_2">
      <pose>0.05 0 0 0 -0 0</pose>
      <parent>link_Hip1_3</parent>
      <child>link_Hip1_2</child>
      <axis>
        <xyz>0 1 0 </xyz>
        <use_parent_model_frame>0</use_parent_model_frame>
        <limit>
          <lower>-0.785398</lower>
          <upper>0.785398</upper>
          <effort>1765.8</effort>
          <velocity>-1</velocity>
          <dissipation>1</dissipation>
        </limit>
      </axis>
    </joint>
    <joint type="revolute" name="joint_link_Hip1_3_link_Hip1_1">
      <pose>-0.0075 0 0 0 -0 0</pose>
      <parent>link_Hip1_3</parent>
      <child>link_Hip1_1</child>
      <axis>
        <xyz>1 0 0 </xyz>
        <use_parent_model_frame>0</use_parent_model_frame>
        <limit>
          <lower>0</lower>
          <upper>0</upper>
          <effort>-1</effort>
          <velocity>-1</velocity>
          <dissipation>1</dissipation>
        </limit>
      </axis>
    </joint>
    <joint type="revolute" name="joint_link_Core_0_link_Hip1_0">
      <pose>-0.0075 0 0 0 -0 0</pose>
      <parent>link_Core_0</parent>
      <child>link_Hip1_0</child>
      <axis>
        <xyz>-1 0 0 </xyz>
        <use_parent_model_frame>0</use_parent_model_frame>
        <limit>
          <lower>0</lower>
          <upper>0</upper>
          <effort>-1</effort>
          <velocity>-1</velocity>
          <dissipation>1</dissipation>
        </limit>
      </axis>
    </joint>
    <joint type="revolute" name="joint_link_Hip1_1_link_UpperLeg1_0">
      <pose>-0.2325 0 0 0 -0 0</pose>
      <parent>link_Hip1_1</parent>
      <child>link_UpperLeg1_0</child>
      <axis>
        <xyz>-1 0 0 </xyz>
        <use_parent_model_frame>0</use_parent_model_frame>
        <limit>
          <lower>0</lower>
          <upper>0</upper>
          <effort>-1</effort>
          <velocity>-1</velocity>
          <dissipation>1</dissipation>
        </limit>
      </axis>
    </joint>
    <joint type="revolute" name="joint_link_Knee1_0_link_Knee1_2">
      <pose>-0.09 0 0 0 -0 0</pose>
      <parent>link_Knee1_0</parent>
      <child>link_Knee1_2</child>
      <axis>
        <xyz>1 0 0 </xyz>
        <use_parent_model_frame>0</use_parent_model_frame>
        <limit>
          <lower>0</lower>
          <upper>0</upper>
          <effort>-1</effort>
          <velocity>-1</velocity>
          <dissipation>1</dissipation>
        </limit>
      </axis>
    </joint>
    <joint type="revolute" name="joint_link_Knee1_3_link_Knee1_2">
      <pose>0.05 0 0 0 -0 0</pose>
      <parent>link_Knee1_3</parent>
      <child>link_Knee1_2</child>
      <axis>
        <xyz>0 1 0 </xyz>
        <use_parent_model_frame>0</use_parent_model_frame>
        <limit>
          <lower>-0.785398</lower>
          <upper>0.785398</upper>
          <effort>1765.8</effort>
          <velocity>-1</velocity>
          <dissipation>1</dissipation>
        </limit>
      </axis>
    </joint>
    <joint type="revolute" name="joint_link_Knee1_3_link_Knee1_1">
      <pose>-0.0075 0 0 0 -0 0</pose>
      <parent>link_Knee1_3</parent>
      <child>link_Knee1_1</child>
      <axis>
        <xyz>1 0 0 </xyz>
        <use_parent_model_frame>0</use_parent_model_frame>
        <limit>
          <lower>0</lower>
          <upper>0</upper>
          <effort>-1</effort>
          <velocity>-1</velocity>
          <dissipation>1</dissipation>
        </limit>
      </axis>
    </joint>
    <joint type="revolute" name="joint_link_UpperLeg1_0_link_Knee1_0">
      <pose>-0.0075 0 0 0 -0 0</pose>
      <parent>link_UpperLeg1_0</parent>
      <child>link_Knee1_0</child>
      <axis>
        <xyz>-1 0 0 </xyz>
        <use_parent_model_frame>0</use_parent_model_frame>
        <limit>
          <lower>0</lower>
          <upper>0</upper>
          <effort>-1</effort>
          <velocity>-1</velocity>
          <dissipation>1</dissipation>
        </limit>
      </axis>
    </joint>
    <joint type="revolute" name="joint_link_Knee1_1_link_LowerLeg1_0">
      <pose>-0.2325 0 0 0 -0 0</pose>
      <parent>link_Knee1_1</parent>
      <child>link_LowerLeg1_0</child>
      <axis>
        <xyz>-1 0 0 </xyz>
        <use_parent_model_frame>0</use_parent_model_frame>
        <limit>
          <lower>0</lower>
          <upper>0</upper>
          <effort>-1</effort>
          <velocity>-1</velocity>
          <dissipation>1</dissipation>
        </limit>
      </axis>
    </joint>
    <joint type="revolute" name="joint_link_Hip2_0_link_Hip2_2">
      <pose>-0.09 0 0 0 -0 0</pose>
      <parent>link_Hip2_0</parent>
      <child>link_Hip2_2</child>
      <axis>
        <xyz>1 0 0 </xyz>
        <use_parent_model_frame>0</use_parent_model_frame>
        <limit>
          <lower>0</lower>
          <upper>0</upper>
          <effort>-1</effort>
          <velocity>-1</velocity>
          <dissipation>1</dissipation>
        </limit>
      </axis>
    </joint>
    <joint type="revolute" name="joint_link_Hip2_3_link_Hip2_2">
      <pose>0.05 0 0 0 -0 0</pose>
      <parent>link_Hip2_3</parent>
      <child>link_Hip2_2</child>
      <axis>
        <xyz>0 1 0 </xyz>
        <use_parent_model_frame>0</use_parent_model_frame>
        <limit>
          <lower>-0.785398</lower>
          <upper>0.785398</upper>
          <effort>1765.8</effort>
          <velocity>-1</velocity>
          <dissipation>1</dissipation>
        </limit>
      </axis>
    </joint>
    <joint type="revolute" name="joint_link_Hip2_3_link_Hip2_1">
      <pose>-0.0075 0 0 0 -0 0</pose>
      <parent>link_Hip2_3</parent>
      <child>link_Hip2_1</child>
      <axis>
        <xyz>1 0 0 </xyz>
        <use_parent_model_frame>0</use_parent_model_frame>
        <limit>
          <lower>0</lower>
          <upper>0</upper>
          <effort>-1</effort>
          <velocity>-1</velocity>
          <dissipation>1</dissipation>
        </limit>
      </axis>
    </joint>
    <joint type="revolute" name="joint_link_Core_0_link_Hip2_0">
      <pose>-0.0075 0 0 0 -0 0</pose>
      <parent>link_Core_0</parent>
      <child>link_Hip2_0</child>
      <axis>
        <xyz>-1 0 0 </xyz>
        <use_parent_model_frame>0</use_parent_model_frame>
        <limit>
          <lower>0</lower>
          <upper>0</upper>
          <effort>-1</effort>
          <velocity>-1</velocity>
          <dissipation>1</dissipation>
        </limit>
      </axis>
    </joint>
    <joint type="revolute" name="joint_link_Hip2_1_link_UpperLeg2_0">
      <pose>-0.2325 0 0 0 -0 0</pose>
      <parent>link_Hip2_1</parent>
      <child>link_UpperLeg2_0</child>
      <axis>
        <xyz>-1 0 0 </xyz>
        <use_parent_model_frame>0</use_parent_model_frame>
        <limit>
          <lower>0</lower>
          <upper>0</upper>
          <effort>-1</effort>
          <velocity>-1</velocity>
          <dissipation>1</dissipation>
        </limit>
      </axis>
    </joint>
    <joint type="revolute" name="joint_link_Knee2_0_link_Knee2_2">
      <pose>-0.09 0 0 0 -0 0</pose>
      <parent>link_Knee2_0</parent>
      <child>link_Knee2_2</child>
      <axis>
        <xyz>1 0 0 </xyz>
        <use_parent_model_frame>0</use_parent_model_frame>
        <limit>
          <lower>0</lower>
          <upper>0</upper>
          <effort>-1</effort>
          <velocity>-1</velocity>
          <dissipation>1</dissipation>
        </limit>
      </axis>
    </joint>
    <joint type="revolute" name="joint_link_Knee2_3_link_Knee2_2">
      <pose>0.05 0 0 0 -0 0</pose>
      <parent>link_Knee2_3</parent>
      <child>link_Knee2_2</child>
      <axis>
        <xyz>0 1 0 </xyz>
        <use_parent_model_frame>0</use_parent_model_frame>
        <limit>
          <lower>-0.785398</lower>
          <upper>0.785398</upper>
          <effort>1765.8</effort>
          <velocity>-1</velocity>
          <dissipation>1</dissipation>
        </limit>
      </axis>
    </joint>
    <joint type="revolute" name="joint_link_Knee2_3_link_Knee2_1">
      <pose>-0.0075 0 0 0 -0 0</pose>
      <parent>link_Knee2_3</parent>
      <child>link_Knee2_1</child>
      <axis>
        <xyz>1 0 0 </xyz>
        <use_parent_model_frame>0</use_parent_model_frame>
        <limit>
          <lower>0</lower>
          <upper>0</upper>
          <effort>-1</effort>
          <velocity>-1</velocity>
          <dissipation>1</dissipation>
        </limit>
      </axis>
    </joint>
    <joint type="revolute" name="joint_link_UpperLeg2_0_link_Knee2_0">
      <pose>-0.0075 0 0 0 -0 0</pose>
      <parent>link_UpperLeg2_0</parent>
      <child>link_Knee2_0</child>
      <axis>
        <xyz>-1 0 0 </xyz>
        <use_parent_model_frame>0</use_parent_model_frame>
        <limit>
          <lower>0</lower>
          <upper>0</upper>
          <effort>-1</effort>
          <velocity>-1</velocity>
          <dissipation>1</dissipation>
        </limit>
      </axis>
    </joint>
    <joint type="revolute" name="joint_link_Knee2_1_link_LowerLeg2_0">
      <pose>-0.2325 0 0 0 -0 0</pose>
      <parent>link_Knee2_1</parent>
      <child>link_LowerLeg2_0</child>
      <axis>
        <xyz>-1 0 0 </xyz>
        <use_parent_model_frame>0</use_parent_model_frame>
        <limit>
          <lower>0</lower>
          <upper>0</upper>
          <effort>-1</effort>
          <velocity>-1</velocity>
          <dissipation>1</dissipation>
        </limit>
      </axis>
    </joint>
    <plugin name="control" filename="libtolmodelcontrol.so">
      <tol:settings xmlns:tol="http://elte.me">
        <tol:motor type="servo" joint="joint_link_Hip1_3_link_Hip1_2" part_id="Hip1" io_id="0" velocityDriven="0" gain="5000"/>
        <tol:motor type="servo" joint="joint_link_Knee1_3_link_Knee1_2" part_id="Knee1" io_id="0" velocityDriven="0" gain="5000"/>
        <tol:motor type="servo" joint="joint_link_Hip2_3_link_Hip2_2" part_id="Hip2" io_id="0" velocityDriven="0" gain="5000"/>
        <tol:motor type="servo" joint="joint_link_Knee2_3_link_Knee2_2" part_id="Knee2" io_id="0" velocityDriven="0" gain="5000"/>
        <tol:brain>
          <tol:neuron id="Core-0" type="simple" layer="input">
            <tol:io_pair part_id="Core" io_id="0"/>
            <tol:gain>1</tol:gain>
          </tol:neuron>
          <tol:neuron id="Core-1" type="simple" layer="input">
            <tol:io_pair part_id="Core" io_id="1"/>
            <tol:gain>1</tol:gain>
          </tol:neuron>
          <tol:neuron id="Core-2" type="simple" layer="input">
            <tol:io_pair part_id="Core" io_id="2"/>
            <tol:gain>1</tol:gain>
          </tol:neuron>
          <tol:neuron id="Core-3" type="simple" layer="input">
            <tol:io_pair part_id="Core" io_id="3"/>
            <tol:gain>1</tol:gain>
          </tol:neuron>
          <tol:neuron id="Core-4" type="simple" layer="input">
            <tol:io_pair part_id="Core" io_id="4"/>
            <tol:gain>1</tol:gain>
          </tol:neuron>
          <tol:neuron id="Core-5" type="simple" layer="input">
            <tol:io_pair part_id="Core" io_id="5"/>
            <tol:gain>1</tol:gain>
          </tol:neuron>
          <tol:neuron id="Hip1-0" type="oscillator" layer="output">
            <tol:io_pair part_id="Hip1" io_id="0"/>
            <tol:period>0.8</tol:period>
            <tol:phase_offset>-0.8</tol:phase_offset>
            <tol:gain>1</tol:gain>
          </tol:neuron>
          <tol:neuron id="Hip2-0" type="oscillator" layer="output">
            <tol:io_pair part_id="Hip2" io_id="0"/>
            <tol:period>0.8</tol:period>
            <tol:phase_offset>-0.95</tol:phase_offset>
            <tol:gain>1</tol:gain>
          </tol:neuron>
          <tol:neuron id="Knee1-0" type="oscillator" layer="output">
            <tol:io_pair part_id="Knee1" io_id="0"/>
            <tol:period>0.8</tol:period>
            <tol:phase_offset>0.2</tol:phase_offset>
            <tol:gain>1</tol:gain>
          </tol:neuron>
          <tol:neuron id="Knee2-0" type="oscillator" layer="output">
            <tol:io_pair part_id="Knee2" io_id="0"/>
            <tol:period>0.8</tol:period>
            <tol:phase_offset>-1</tol:phase_offset>
            <tol:gain>1</tol:gain>
          </tol:neuron>
        </tol:brain>
      </tol:settings>
    </plugin>
  </model>
</sdf>
